<robot name="OSU vLBV300 Volturnus">
  <link name="body" />
  <link name="gripper1" />
  <link name="gripper2" />
  <link name="gripper3" />

  <joint name="joint_gripper1" type="continuous">
    <parent link="body"/>
    <child link="gripper1"/>
    <origin xyz="0.5 0.1 0.1" rpy="0 0 1.57" />
    <axis xyz="0 1 0" />
  </joint>

  <joint name="joint_gripper2" type="continuous">
    <parent link="body"/>
    <child link="gripper2"/>
    <origin xyz="0.5 0.1 0.1" rpy="0 0 1.57" />
    <axis xyz="0 -0.707 -0.707" />
  </joint>

  <joint name="joint_gripper3" type="continuous">
    <child link="gripper3"/>
    <parent link="body"/>
    <origin xyz="0.5 0.1 0.1" rpy="0 0 1.57" />
    <axis xyz="0 0.707 0.707" />
  </joint>
</robot>
